const promise = new Promise((resolve, reject) => {
    // Skapar ett random nummer mellan 0-1.
    const randomNumber = Math.random();

    // 2 sekunders timeout, sedan k√∂rs funktionen inuti.
    setTimeout(() => {
        if (randomNumber > 0.5) {
            // Resolve uppfyller promisen och skickar tillbaka information, i detta fall en array av filmer.
            resolve(['Braveheart', 'Troy', 'Die Hard']);
        } else {
            // Reject throwar ett error, och skickar tillbaka informationen. Detta ska catchas i en .catch() eller catch{}.
            reject('Unable to retrieve movies, sucks to be you');
        }
    }, 2000);
});


function getMovies(){
    return promise;
}

// // Vi kan anv√§nda oss av .then, .catch och .finally
getMovies()
    .then(res => console.log(res))
    .catch(error => console.log(error))
    .finally(() => console.log('KLART!'));


// // Eller await, wrappat i try{}.
try{
    const response = await getMovies();
    console.log(response);
} catch(error){
    console.log(error);
} finally{
    console.log('Jag √§r nu klar, ingen aning om det gick bra eller ej ü§∑üèª‚Äç‚ôÇÔ∏è');
}


// Vi kan hantera errors som uppst√•r, √§ven fast dem inte har att g√∂ra med promises eller asynkronitet.
try{
    // "throw" G√∂r s√• att ett error uppst√•r i Javascript
    // "new Error()" skapar ett nytt error objekt, den tar emot ett meddelande som l√§ggs in i error objektet.
    // Error objektet inneh√•ller v√§rdefull info, framf√∂rallt call-stacken.
    throw new Error('Ett error uppstod');
} catch(error) {
    console.log(error)
}